Workbook

Sheet MARD
A1: 🔴 MARD
A3: Totalt antall rader | B3: =COUNTA(A11:A1016) -> 1006
A4: Unike MATNR totalt | B4: {=SUMPRODUCT(1/COUNTIF(A11:A1016,A11:A1016))} -> 1006
A5: Aktive (TOTAL_STOCK > 0) | B5: =COUNTIF(Q11:Q1016,">0") -> 709
A6: Inaktive (TOTAL_STOCK = 0) | B6: =COUNTIF(Q11:Q1016,0) -> 297
A7: Unike aktive MATNR | B7: {=SUMPRODUCT((Q11:Q1016>0)*(1/COUNTIF(A11:A1016,A11:A1016)))} -> 709
A8: Andel aktive (%) | B8: =B5/B3 -> 0.70477137
A10: Material | B10: Fabrikk | C10: Lager | D10: Vedlikeholdsstatus | E10: Sl.merking lagernivå | F10: År innev. periode | G10: Inneværende periode | H10: Fritt disponibel (LABST) | I10: Sperret (EINME) | J10: Lagerbeholdning | K10: Lagerbeholdn. - f.å. | L10: Lageradresse | M10: Dato for siste LT | N10: Opprettingsdato | O10: MARDH-post | P10: Regnskapsår | Q10: TOTAL_STOCK | R10: STATUS
A11: =[1]Data!A2 -> 4000005 | B11: =[1]Data!B2 -> 3300 | C11: =[1]Data!C2 -> 3001 | D11: =[1]Data!D2 -> DL | E11: =[1]Data!E2 | F11: =[1]Data!F2 -> 2026 | G11: =[1]Data!G2 -> 2 | H11: =[1]Data!H2 -> 52 | ... R11: =[1]Data!R2
A12: =[1]Data!A3 -> 4000009 | B12: =[1]Data!B3 -> 3300 | C12: =[1]Data!C3 -> 3001 | D12: =[1]Data!D3 -> DL | E12: =[1]Data!E3 | F12: =[1]Data!F3 -> 2024 | G12: =[1]Data!G3 -> 9 | H12: =[1]Data!H3 -> 0 | ... R12: =[1]Data!R3 -> INAKTIV
A13: =[1]Data!A4 -> 4000014 | B13: =[1]Data!B4 -> 3300 | C13: =[1]Data!C4 -> 3001 | D13: =[1]Data!D4 -> L | E13: =[1]Data!E4 | F13: =[1]Data!F4 -> 2026 | G13: =[1]Data!G4 -> 3 | H13: =[1]Data!H4 -> 302 | ... R13: =[1]Data!R4
A14: =[1]Data!A5 -> 4000023 | B14: =[1]Data!B5 -> 3300 | C14: =[1]Data!C5 -> 3001 | D14: =[1]Data!D5 -> DL | E14: =[1]Data!E5 | F14: =[1]Data!F5 -> 2026 | G14: =[1]Data!G5 -> 3 | H14: =[1]Data!H5 -> 574 | ... R14: =[1]Data!R5
A15: =[1]Data!A6 -> 4000024 | B15: =[1]Data!B6 -> 3300 | C15: =[1]Data!C6 -> 3001 | D15: =[1]Data!D6 -> DL | E15: =[1]Data!E6 | F15: =[1]Data!F6 -> 2026 | G15: =[1]Data!G6 -> 2 | H15: =[1]Data!H6 -> 2130 | ... R15: =[1]Data!R6
A16: =[1]Data!A7 -> 4000027 | B16: =[1]Data!B7 -> 3300 | C16: =[1]Data!C7 -> 3001 | D16: =[1]Data!D7 -> L | E16: =[1]Data!E7 | F16: =[1]Data!F7 -> 2026 | G16: =[1]Data!G7 -> 2 | H16: =[1]Data!H7 -> 184 | ... R16: =[1]Data!R7
A17: =[1]Data!A8 -> 4000032 | B17: =[1]Data!B8 -> 3300 | C17: =[1]Data!C8 -> 3001 | D17: =[1]Data!D8 -> DL | E17: =[1]Data!E8 | F17: =[1]Data!F8 -> 2022 | G17: =[1]Data!G8 -> 2 | H17: =[1]Data!H8 -> 0 | ... R17: =[1]Data!R8 -> INAKTIV
A18: =[1]Data!A9 -> 4000060 | B18: =[1]Data!B9 -> 3300 | C18: =[1]Data!C9 -> 3001 | D18: =[1]Data!D9 -> L | E18: =[1]Data!E9 | F18: =[1]Data!F9 -> 2026 | G18: =[1]Data!G9 -> 3 | H18: =[1]Data!H9 -> 1900 | ... R18: =[1]Data!R9
A19: =[1]Data!A10 -> 4000061 | B19: =[1]Data!B10 -> 3300 | C19: =[1]Data!C10 -> 3001 | D19: =[1]Data!D10 -> L | E19: =[1]Data!E10 | F19: =[1]Data!F10 -> 2026 | G19: =[1]Data!G10 -> 3 | H19: =[1]Data!H10 -> 2600 | ... R19: =[1]Data!R10
A20: =[1]Data!A11 -> 4000062 | B20: =[1]Data!B11 -> 3300 | C20: =[1]Data!C11 -> 3001 | D20: =[1]Data!D11 -> L | E20: =[1]Data!E11 | F20: =[1]Data!F11 -> 2024 | G20: =[1]Data!G11 -> 11 | H20: =[1]Data!H11 -> 0 | ... R20: =[1]Data!R11 -> INAKTIV
A21: =[1]Data!A12 -> 4000063 | B21: =[1]Data!B12 -> 3300 | C21: =[1]Data!C12 -> 3001 | D21: =[1]Data!D12 -> L | E21: =[1]Data!E12 | F21: =[1]Data!F12 -> 2021 | G21: =[1]Data!G12 -> 11 | H21: =[1]Data!H12 -> 0 | ... R21: =[1]Data!R12 -> INAKTIV
A22: =[1]Data!A13 -> 4000065 | B22: =[1]Data!B13 -> 3300 | C22: =[1]Data!C13 -> 3001 | D22: =[1]Data!D13 -> L | E22: =[1]Data!E13 | F22: =[1]Data!F13 -> 2026 | G22: =[1]Data!G13 -> 3 | H22: =[1]Data!H13 -> 7000 | ... R22: =[1]Data!R13
... A1016: =[1]Data!A1007 -> 4049385 | B1016: =[1]Data!B1007 -> 3300 | C1016: =[1]Data!C1007 -> 3001 | D1016: =[1]Data!D1007 -> DL | E1016: =[1]Data!E1007 | F1016: =[1]Data!F1007 -> 2026 | G1016: =[1]Data!G1007 -> 2 | H1016: =[1]Data!H1007 -> 0 | ... R1016: =[1]Data!R1007 -> INAKTIV

Sheet MDMA
A1: 🔴 MDMA
A3: Totalt antall MATNR | B3: 871
A4: ABC dekningsprosent | B4: 0.8278
A5: XYZ dekningsprosent | B5: 0.5006
A6: ZZABC blank (mangler) | B6: 150
A7: ZZXYZ blank (mangler) | B7: 435
A8: Vanligste ABC-klasse | B8: C
A10: Material | B10: MRP-område | C10: MRP-område: Fabrikk | D10: MRP-type | E10: Materialplanlegger | F10: MRP-gruppe | G10: Bestillingspunkt | H10: Partiberegningsmetode | I10: Spesialanskaffelse | J10: Fast partistørrelse | K10: Slettemerking | L10: Aut. annullering | M10: Vedlikeholdsstatus | N10: Planl. leveringstid | O10: Endret av | P10: Endret den | Q10: Endret kl. | R10: Produkt | S10: Lokal.prod.-ID | T10: VM-behandlingstid | U10: Fastsetting sikkerhLagermet. | V10: Migreringsstatus | W10: ABC-indikator | X10: XYZ Indicator | Y10: ABC_COVERAGE | Z10: XYZ_COVERAGE
A11: 4000005 | B11: 3300_3001 | C11: 3300 | D11: Z1 | E11: 301 | F11: 0 | G11: 20 | H11: FX | I11: YB | J11: 50 | M11: D | N11: 0 | O11: HAUHIL | P11: 45924 | Q11: 0.36790509 | R11: BD89761801441EEF99BF6CB438ECC92D | S11: lObs60547k{PlsoqEEp9BG | U11: X | V11: 1 | X11: X | Y11: MANGLER | Z11: OK
A12: 4000009 | B12: 3300_3001 | C12: 3300 | D12: ND | E12: 301 | F12: 0 | G12: 594 | H12: FX | I12: 20 | J12: 180 | K12: X | M12: D | N12: 0 | O12: ALOS | P12: 45547 | Q12: 0.59811343 | R12: BD89761801441EEF99BF5A8198F4074E | S12: lObs60547k{Plrg1cFG7JW | X12: X | Y12: MANGLER | Z12: OK
A13: 4000014 | B13: 3300_3001 | C13: 3300 | D13: Z1 | E13: 301 | F13: 0 | G13: 400 | H13: FX | I13: YB | J13: 250 | M13: D | N13: 0 | O13: HAUHIL | P13: 46007 | Q13: 0.32560185 | R13: 0 | T13: 1,00 | U13: X | V13: 1 | W13: A | X13: X | Y13: OK | Z13: OK
A14: 4000023 | B14: 3300_3001 | C14: 3300 | D14: Z1 | E14: 301 | F14: 0 | G14: 400 | H14: FX | I14: 20 | J14: 1440 | M14: D | N14: 0 | O14: ERLI | P14: 45356 | Q14: 0.31668981 | R14: 3627711FA3061EED8C864CE1DFDA20FD | S14: DYTn7wC67ksCXapXtzeW}G | U14: X | V14: 1 | W14: A | X14: Y | Y14: OK | Z14: OK
A15: 4000024 | B15: 3300_3001 | C15: 3300 | D15: Z1 | E15: 301 | F15: 0 | G15: 1800 | H15: FX | I15: 20 | J15: 1440 | M15: D | N15: 0 | O15: ABKJ | P15: 45947 | Q15: 0.33091435 | R15: 3627711FA3061EDD8CCD6D43992C52D7 | S15: DYTn7wC67jsCpMr3cInIrm | U15: X | V15: 1 | W15: A | X15: Y | Y15: OK | Z15: OK
A16: 4000027 | B16: 3300_3001 | C16: 3300 | D16: Z1 | E16: 301 | F16: 0 | G16: 10 | H16: FX | I16: YB | J16: 40 | M16: D | N16: 5 | O16: HAUHIL | P16: 46052 | Q16: 0.51880787 | R16: 36277CA1D60A1EDC87A69674BF833147 | S16: DYTyeTOA7jo7ffPqluCnHm | T16: 1,00 | U16: X | V16: 1 | W16: C | X16: Y | Y16: OK | Z16: OK
A17: 4000060 | B17: 3300_3001 | C17: 3300 | D17: Z1 | E17: 301 | F17: 0 | G17: 1200 | H17: FX | I17: YB | J17: 1600 | M17: D | N17: 0 | O17: HAUHIL | P17: 46057 | Q17: 0.54243056 | R17: 36277CA1D60A1EDC87A6969901185147 | S17: DYTyeTOA7jo7ffQP0HXHHm | U17: X | V17: 1 | W17: B | X17: X | Y17: OK | Z17: OK
A18: 4000061 | B18: 3300_3001 | C18: 3300 | D18: Z1 | E18: 301 | F18: 0 | G18: 1500 | H18: FX | I18: ZI | J18: 2600 | M18: D | N18: 0 | O18: ERLI | P18: 45687 | Q18: 0.3434375 | R18: 36277CA1D60A1EDC87A696990118F147 | S18: DYTyeTOA7jo7ffQP0HZnHm | U18: X | V18: 1 | W18: A | X18: X | Y18: OK | Z18: OK
A19: 4000062 | B19: 3300_3001 | C19: 3300 | D19: ND | G19: 0 | J19: 0 | M19: D | N19: 0 | O19: TOVKVA | P19: 45040 | Q19: 0.69572917 | R19: 36277CA1D60A1EDC87A69699011A3147 | S19: DYTyeTOA7jo7ffQP0HenHm | U19: X | V19: 1 | W19: C | X19: X | Y19: OK | Z19: OK
A20: 4000063 | B20: 3300_3001 | C20: 3300 | D20: ND | G20: 0 | I20: ZI | J20: 0 | M20: D | N20: 0 | O20: ANDSIS | P20: 45204 | Q20: 0.44590278 | R20: 0 | U20: X | V20: 1 | W20: C | X20: X | Y20: OK | Z20: OK
A21: 4000065 | B21: 3300_3001 | C21: 3300 | D21: Z1 | E21: 301 | F21: 0 | G21: 8000 | H21: FX | I21: ZI | J21: 20000 | M21: D | N21: 0 | O21: TOVKVA | P21: 44703 | Q21: 0.92457176 | R21: 36277CA1D60A1EDC87A69699011CB147 | S21: DYTyeTOA7jo7ffQP0HonHm | U21: X | V21: 1 | W21: A | X21: X | Y21: OK | Z21: OK
A22: 4000066 | B22: 3300_3001 | C22: 3300 | D22: Z1 | E22: 301 | F22: 0 | G22: 200 | H22: FX | I22: YB | J22: 100 | M22: D | N22: 0 | O22: HAUHIL | P22: 46007 | Q22: 0.30540509 | R22: 0 | T22: 1,00 | U22: X | V22: 1 | W22: C | X22: X | Y22: OK | Z22: OK
A23: 4000067 | B23: 3300_3001 | C23: 3300 | D23: Z1 | E23: 301 | F23: 0 | G23: 25 | H23: FX | I23: YB | J23: 100 | M23: D | N23: 5 | O23: HAUHIL | P23: 45924 | Q23: 0.38189815 | R23: 0 | T23: 1,00 | U23: X | V23: 1 | W23: C | Y23: OK | Z23: MANGLER
A24: 4000069 | B24: 3300_3001 | C24: 3300 | D24: ND | G24: 0 | J24: 0 | M24: D | N24: 0 | O24: ANDSIS | P24: 45204 | Q24: 0.44784722 | R24: 36277CA1D60A1EDC87A69699011E9147 | S24: DYTyeTOA7jo7ffQP0HwHHm | U24: X | V24: 1 | W24: C | X24: X | Y24: OK | Z24: OK
A25: 4000072 | B25: 3300_3001 | C25: 3300 | D25: Z1 | E25: 301 | F25: 0 | G25: 1000 | H25: FX | I25: YB | J25: 480 | M25: D | N25: 0 | O25: HAUHIL | P25: 45988 | Q25: 0.2765162 | R25: 36277CA1D60A1EDC87A6969901207147 | S25: DYTyeTOA7jo7ffQP0I1nHm | U25: X | V25: 1 | W25: B | X25: X | Y25: OK | Z25: OK
A26: 4000077 | B26: 3300_3001 | C26: 3300 | D26: Z1 | E26: 301 | F26: 0 | G26: 400 | H26: FX | I26: ZI | J26: 200 | M26: D | N26: 0 | O26: ERLI | P26: 45489 | Q26: 0.32076389 | R26: 36277CA1D60A1EDC87A6969901211147 | S26: DYTyeTOA7jo7ffQP0I4HHm | T26: 1,00 | U26: X | V26: 1 | W26: B | X26: Y | Y26: OK | Z26: OK
A27: 4000078 | B27: 3300_3001 | C27: 3300 | D27: Z1 | E27: 301 | F27: 0 | G27: 1000 | H27: FX | I27: 20 | J27: 1000 | M27: D | N27: 0 | O27: HAUHIL | P27: 46035 | Q27: 0.27616898 | R27: 36277CA1D60A1EDC87A696990121B147 | S27: DYTyeTOA7jo7ffQP0I6nHm | T27: 1,00 | U27: X | V27: 1 | W27: C | X27: X | Y27: OK | Z27: OK
A28: 4000084 | B28: 3300_3001 | C28: 3300 | D28: Z1 | E28: 301 | F28: 0 | G28: 106 | H28: FX | I28: 20 | J28: 56 | M28: D | N28: 5 | O28: HAUHIL | P28: 45446 | Q28: 0.36844907 | R28: 36277CA1D60A1EDC87A696990122F147 | S28: DYTyeTOA7jo7ffQP0IBnHm | T28: 1,00 | U28: X | V28: 1 | W28: C | X28: X | Y28: OK | Z28: OK
A29: 4000090 | B29: 3300_3001 | C29: 3300 | D29: Z1 | E29: 301 | F29: 0 | G29: 3000 | H29: FX | I29: 20 | J29: 1200 | M29: D | N29: 0 | O29: HAUHIL | P29: 45306 | Q29: 0.30049769 | R29: 36277CA1D60A1EDC87A6969901239147 | S29: DYTyeTOA7jo7ffQP0IEHHm | T29: 1,00 | U29: X | V29: 1 | W29: B | Y29: OK | Z29: MANGLER
A30: 4000094 | B30: 3300_3001 | C30: 3300 | D30: Z1 | E30: 301 | F30: 0 | G30: 3500 | H30: FX | I30: YB | J30: 4000 | M30: D | N30: 0 | O30: HAUHIL | P30: 45973 | Q30: 0.28586806 | R30: 3627711FA3061EED95D22DCEA2B66BBB | S30: DYTn7wC67ksLqYtEehPhkm | U30: X | V30: 1 | W30: A | X30: Y | Y30: OK | Z30: OK
A31: 4000108 | B31: 3300_3001 | C31: 3300 | D31: Z1 | E31: 301 | F31: 0 | G31: 3000 | H31: FX | I31: 20 | J31: 600 | M31: D | N31: 5 | O31: ANDSIS | P31: 45358 | Q31: 0.38288194 | R31: 36277CA1D60A1EDC87A6969901275147 | S31: DYTyeTOA7jo7ffQP0ITHHm | T31: 1,00 | U31: X | V31: 1 | W31: A | X31: Y | Y31: OK | Z31: OK
A32: 4000273 | B32: 3300_3001 | C32: 3300 | D32: Z1 | E32: 301 | F32: 0 | G32: 9000 | H32: FX | I32: YB | J32: 11520 | M32: D | N32: 0 | O32: HAUHIL | P32: 45924 | Q32: 0.53972222 | R32: 0 | U32: X | V32: 1 | W32: A | X32: Y | Y32: OK | Z32: OK
A33: 4000274 | B33: 3300_3001 | C33: 3300 | D33: Z1 | E33: 301 | F33: 0 | G33: 17280 | H33: FX | I33: YB | J33: 8640 | M33: D | N33: 0 | O33: HAUHIL | P33: 45636 | Q33: 0.28885417 | R33: 0 | U33: X | V33: 1 | W33: A | X33: X | Y33: OK | Z33: OK
A34: 4000275 | B34: 3300_3001 | C34: 3300 | D34: Z1 | E34: 301 | F34: 0 | G34: 700 | H34: FX | I34: ZJ | J34: 1000 | M34: D | N34: 0 | O34: ABKJ | P34: 45552 | Q34: 0.55476852 | R34: 36277CA1D60A1EDC87A696E593F43147 | S34: DYTyeTOA7jo7ffRba}GnHm | U34: X | V34: 1 | W34: C | X34: X | Y34: OK | Z34: OK
A35: 4000276 | B35: 3300_3001 | C35: 3300 | D35: Z1 | E35: 301 | F35: 0 | G35: 1200 | H35: FX | I35: YB | J35: 1000 | M35: D | N35: 0 | O35: HAUHIL | P35: 45993 | Q35: 0.28025463 | R35: 36277CA1D60A1EDC87A696E593F4D147 | S35: DYTyeTOA7jo7ffRba}JHHm | U35: X | V35: 1 | W35: C | X35: X | Y35: OK | Z35: OK
A36: 4000279 | B36: 3300_3001 | C36: 3300 | D36: Z1 | E36: 301 | F36: 0 | G36: 1500 | H36: FX | I36: YB | J36: 1000 | M36: D | N36: 0 | O36: HAUHIL | P36: 45720 | Q36: 0.3199537 | R36: 0 | T36: 1,00 | U36: X | V36: 1 | W36: B | X36: Y | Y36: OK | Z36: OK
A37: 4000280 | B37: 3300_3001 | C37: 3300 | D37: ND | E37: 301 | F37: 0 | G37: 8000 | H37: FX | I37: 20 | J37: 2000 | K37: X | M37: D | N37: 0 | O37: KOVE | P37: 44495 | Q37: 0.39685185 | R37: 36277CA1D60A1EDC87A696E593F75147 | S37: DYTyeTOA7jo7ffRba}THHm | W37: C | Y37: OK | Z37: MANGLER
A38: 4000286 | B38: 3300_3001 | C38: 3300 | D38: Z1 | E38: 301 | F38: 0 | G38: 1500 | H38: FX | I38: YB | J38: 3000 | M38: D | N38: 0 | O38: HAUHIL | P38: 45728 | Q38: 0.27861111 | R38: 36277CA1D60A1EDC87A696E593F89147 | S38: DYTyeTOA7jo7ffRba}YHHm | U38: X | V38: 1 | W38: A | X38: X | Y38: OK | Z38: OK
A39: 4000287 | B39: 3300_3001 | C39: 3300 | D39: Z1 | E39: 301 | F39: 0 | G39: 2000 | H39: FX | I39: YB | J39: 3000 | M39: D | N39: 0 | O39: HAUHIL | P39: 45726 | Q39: 0.30553241 | R39: 36277CA1D60A1EDC87A696E593F93147 | S39: DYTyeTOA7jo7ffRba}anHm | U39: X | V39: 1 | W39: A | X39: X | Y39: OK | Z39: OK
A40: 4000288 | B40: 3300_3001 | C40: 3300 | D40: Z1 | E40: 301 | F40: 0 | G40: 1500 | H40: FX | I40: YB | J40: 2000 | M40: D | N40: 0 | O40: HAUHIL | P40: 46070 | Q40: 0.32168981 | R40: 36277CA1D60A1EDC87A696E593FB1147 | S40: DYTyeTOA7jo7ffRba}iHHm | U40: X | V40: 1 | W40: A | X40: X | Y40: OK | Z40: OK
A41: 4000290 | B41: 3300_3001 | C41: 3300 | D41: Z1 | E41: 301 | F41: 0 | G41: 500 | H41: FX | I41: YB | J41: 500 | M41: D | N41: 0 | O41: HAUHIL | P41: 45947 | Q41: 0.32868056 | R41: 36277CA1D60A1EDC87A6970BA4371147 | S41: DYTyeTOA7jo7ffSBf3SHHm | T41: 1,00 | U41: X | V41: 1 | W41: C | X41: X | Y41: OK | Z41: OK
A42: 4000291 | B42: 3300_3001 | C42: 3300 | D42: Z1 | E42: 301 | F42: 0 | G42: 355 | H42: FX | I42: YB | J42: 200 | M42: D | N42: 5 | O42: THOJEN | P42: 46036 | Q42: 0.42037037 | R42: 0 | T42: 1,00 | U42: X | V42: 1 | W42: C | X42: X | Y42: OK | Z42: OK
...

Sheet MARA
A1: 🟢 MARA
A3: Totalt antall rader | B3: 1006
A4: Unike MATNR | B4: 1006
A5: Unike materialtyper (MTART) | B5: 1
A6: Unike varegrupper (MATKL) | B6: {=SUMPRODUCT(1/COUNTIF(C11:C1016,C11:C1016))} -> 90
A7: Vanligste enhet (MEINS) | B7: STK
A8: Andel STK | B8: =COUNTIF(D11:D1016,"STK")/COUNTA(D11:D1016) -> 0.85387674
A10: MATNR | B10: MTART | C10: MATKL | D10: MEINS
A11: 4000005 | B11: ZHAW | C11: 10080301 | D11: STK
A12: 4000009 | B12: ZHAW | C12: 10080301 | D12: PSE
A13: 4000014 | B13: ZHAW | C13: 10050505 | D13: STK
A14: 4000023 | B14: ZHAW | C14: 10080401 | D14: STK
A15: 4000024 | B15: ZHAW | C15: 10080401 | D15: STK
A16: 4000027 | B16: ZHAW | C16: 10080401 | D16: STK
A17: 4000032 | B17: ZHAW | C17: 10020403 | D17: PSE
A18: 4000060 | B18: ZHAW | C18: 10050103 | D18: STK
A19: 4000061 | B19: ZHAW | C19: 10050103 | D19: STK
A20: 4000062 | B20: ZHAW | C20: 10050103 | D20: STK
A21: 4000063 | B21: ZHAW | C21: 10050103 | D21: STK
A22: 4000065 | B22: ZHAW | C22: 10050103 | D22: STK
... A1016: 4049385 | B1016: ZHAW | C1016: 10050103 | D1016: STK

Sheet MAKT
A1: 🟢 MAKT
A3: Totalt antall rader | B3: =COUNTA(A11:A1016) -> 1006
A4: Unike materialnr (MATNR) | B4: =COUNTA(A11:A1016) -> 1006
A5: Gjennomsnittlig beskrivelseslengde | B5: {=AVERAGE(LEN(B11:B1016))} -> 32.207753
A6: Materialer uten beskrivelse | B6: =COUNTBLANK(B11:B1016) -> 0
A7: Lengste beskrivelse (tegn) | B7: {=MAX(LEN(B11:B1016))} -> 40
A8: Korteste beskrivelse (tegn) | B8: {=MIN(LEN(B11:B1016))} -> 12
A10: Material | B10: Materialbeskrivelse
A11: 4000005 | B11: Filter steril Diasafe Plus
A12: 4000009 | B12: Bikarbonatpulver til 5008 900g
A13: 4000014 | B13: Forstøverbeger medikament m/munnstykke
A14: 4000023 | B14: Ernæringssett Infinity pack
A15: 4000024 | B15: Ernæringssett Flocare Infin mobil
A16: 4000027 | B16: Sonde ernæring ENFit Ch6/60cm
A17: 4000032 | B17: Væske infu NaCl 9mg/ml pose 500ml
A18: 4000060 | B18: Kran 3-veis luerlock u/slange
A19: 4000061 | B19: Kran 3-veis m/slange 10cm
A20: 4000062 | B20: Kran 3-veis m/slange 100cm
A21: 4000063 | B21: Infusett m/lufting 180cm
... A1016: 4049385 | B1016: Ventil Nålfri enkel BD

Sheet MARC
A1: 🔴 MARC
A3: Totalt antall MATNR | B3: 871
A4: Unike MATNR (etter dedup) | B4: 871
A5: MATNR m/blank ABC-indikator | B5: 168
A6: ABC dekningsprosent | B6: =COUNTA(B11:B881)/COUNTA(A11:A881) -> 0.80711825
A7: Vanligste ABC-klasse | B7: C
A8: Manglende kolonner | B8: EISBE, MINBE, MABST
A10: MATNR | B10: ABC-indikator
A11: 4000005 | B11: C
A12: 4000009
A13: 4000014 | B13: C
A14: 4000023
A15: 4000024
A16: 4000027 | B16: C
A17: 4000060 | B17: C
A18: 4000061 | B18: B
A19: 4000062 | B19: C
A20: 4000063 | B20: A
A21: 4000065 | B21: A
A22: 4000066 | B22: C
A23: 4000067 | B23: C
A24: 4000069 | B24: B
A25: 4000072 | B25: C
A26: 4000077 | B26: C
A27: 4000078 | B27: C
... A163: 4001130 | B163: C
A164: 4001133
A165: 4001134
A166: 4001135
A167: 4001136
A168: 4001137
A169: 4001138 | B169: C
A170: 4001160 | B170: C
A171: 4001161
A172: 4001194 | B172: C
A173: 4001207 | B173: C
A174: 4001208 | B174: C
A175: 4001211 | B175: C
A176: 4001215 | B176: C
A177: 4001216 | B177: C
...

Sheet MBEW
A1: 🟢 MBEW
A3: Totalt antall materialer | B3: =COUNTA(A11:A881) -> 871
A4: Gjennomsnittspris (UNIT_PRICE) | B4: =AVERAGE(B11:B881) -> 429.34199
A5: Medianpris | B5: =MEDIAN(B11:B881) -> 16.94
A6: Maks pris | B6: =MAX(B11:B881) -> 119438.31
A7: Min pris (> 0) | B7: =_xlfn.MINIFS(B11:B881,B11:B881,">0") -> 0.0001
A8: Andel V-priser (bevegelig gj.sn.) | B8: =COUNTIF(C11:C881,"V")/COUNTA(C11:C881) -> 0.95407577
A10: MATNR | B10: UNIT_PRICE | C10: VPRSV | D10: PEINH | E10: PRIS_STATUS
A11: 4000005 | B11: 2064.73 | C11: V | D11: 1
A12: 4000009 | B12: 79.89 | C12: V | D12: 1
A13: 4000014 | B13: 10.25 | C13: V | D13: 1
A14: 4000023 | B14: 23.41 | C14: V | D14: 1
A15: 4000024 | B15: 22.39 | C15: V | D15: 1
A16: 4000027 | B16: 39.69 | C16: V | D16: 1
A17: 4000060 | B17: 2.77 | C17: V | D17: 1
A18: 4000061 | B18: 4.26 | C18: V | D18: 1
A19: 4000062 | B19: 7.48 | C19: V | D19: 1
A20: 4000063 | B20: 4.91 | C20: V | D20: 1
A21: 4000065 | B21: 0.2602 | C21: V | D21: 100
A22: 4000066 | B22: 6.9 | C22: V | D22: 1
... A362: 4003916 | B362: 12.78 | C362: V | D362: 1
A363: 4003922 | B363: 0 | C363: V | D363: 1 | E363: EKSKLUDER
A364: 4004010 | B364: 0.01 | C364: S | D364: 1
A365: 4004015 | B365: 0.7613 | C365: V | D365: 100
A366: 4004018 | B366: 0.01 | C366: S | D366: 1
A367: 4004037 | B367: 31.21 | C367: V | D367: 1
A368: 4004039 | B368: 3.07 | C368: V | D368: 1
A369: 4004041 | B369: 7.2 | C369: V | D369: 1
A370: 4004049 | B370: 1.2229 | C370: V | D370: 100
A371: 4004054 | B371: 9.51 | C371: V | D371: 1
A372: 4004067 | B372: 185 | C372: V | D372: 1
A373: 4004068 | B373: 88 | C373: V | D373: 1
A374: 4004070 | B374: 18.84 | C374: V | D374: 1
A375: 4004071 | B375: 51.48 | C375: V | D375: 1
... A881: 4049360 | B881: 2.6402 | C881: V | D881: 100

Sheet MSEG
A1: 🟢 MSEG
A3: Totalt antall materialer | B3: =COUNTA(A11:A732) -> 722
A4: Aktive måneder (snitt) | B4: =AVERAGE(Z11:Z732) -> 49793.706
A5: Total forbruk (alle MATNR) | B5: =SUM(Y11:Y732) -> 1564115
A6: Gjennomsnittlig CV | B6: =AVERAGE(AA11:AA732) -> 19.695291
A7: Antall med CV > 1.0 (ustabil) | B7: =COUNTIF(AA11:AA732,">1") -> 709
A8: Antall med STATUS 'INAKTIV' | B8: =COUNTIF(AB11:AB732,"*INAKTIV*") -> 0
A10: MATNR | B10: 2024-01 | C10: 2024-02 | D10: 2024-03 | E10: 2024-04 | F10: 2024-05 | G10: 2024-06 | H10: 2024-07 | I10: 2024-08 | J10: 2024-09 | K10: 2024-10 | L10: 2024-11 | M10: 2024-12 | N10: 2025-01 | O10: 2025-02 | P10: 2025-03 | Q10: 2025-04 | R10: 2025-05 | S10: 2025-06 | T10: 2025-07 | U10: 2025-08 | V10: 2025-09 | W10: 2025-10 | X10: 2025-11 | Y10: 2025-12 | Z10: TOTAL | AA10: ACTIVE_MONTHS | AB10: CV | AC10: STATUS
A11: 4000005 | B11: 0 | C11: 0 | D11: 0 | E11: 0 | F11: 0 | G11: 0 | H11: 0 | I11: 0 | J11: 50 | K11: 60 | L11: 34 | M11: 60 | N11: 30 | O11: 50 | P11: 24 | Q11: 70 | R11: 8 | S11: 60 | T11: 60 | U11: 10 | V11: 30 | W11: 20 | X11: 10 | Y11: 78 | Z11: 654 | AA11: 16 | AB11: 0.9697
A12: 4000014 | B12: 1512 | C12: 1162 | D12: 1184 | E12: 999 | F12: 1347 | G12: 897 | H12: 1131 | I12: 958 | J12: 1409 | K12: 1333 | L12: 1347 | M12: 1236 | N12: 1489 | O12: 1566 | P12: 1470 | Q12: 1211 | R12: 1040 | S12: 972 | T12: 975 | U12: 1090 | V12: 1242 | W12: 1434 | X12: 1185 | Y12: 1438 | Z12: 29627 | AA12: 24 | AB12: 0.1583
A13: 4000023 | B13: 840 | C13: 930 | D13: 1050 | E13: 820 | F13: 640 | G13: 780 | H13: 1000 | I13: 930 | J13: 900 | K13: 995 | L13: 1095 | M13: 1100 | N13: 1050 | O13: 1370 | P13: 1400 | Q13: 1120 | R13: 1020 | S13: 1010 | T13: 995 | U13: 930 | V13: 1260 | W13: 1110 | X13: 820 | Y13: 1140 | Z13: 24305 | AA13: 24 | AB13: 0.1716
A14: 4000024 | B14: 300 | C14: 30 | D14: 60 | E14: 120 | F14: 750 | G14: 1530 | H14: 1170 | I14: 540 | J14: 120 | K14: 60 | L14: 1590 | M14: 90 | N14: 60 | O14: 60 | P14: 120 | Q14: 780 | R14: 210 | S14: 570 | T14: 1170 | U14: 540 | V14: 90 | W14: 2280 | X14: 30 | Y14: 630 | Z14: 12900 | AA14: 24 | AB14: 1.1109
A15: 4000027 | B15: 28 | C15: 44 | D15: 52 | E15: 28 | F15: 0 | G15: 24 | H15: 4 | I15: 44 | J15: 4 | K15: 34 | L15: 4 | M15: 39 | N15: 24 | O15: 48 | P15: 64 | Q15: 20 | R15: 14 | S15: 24 | T15: 20 | U15: 30 | V15: 4 | W15: 22 | X15: 10 | Y15: 10 | Z15: 595 | AA15: 23 | AB15: 0.681
A16: 4000060 | B16: 5200 | C16: 5400 | D16: 4000 | E16: 6100 | F16: 4700 | G16: 4600 | H16: 4050 | I16: 4100 | J16: 5600 | K16: 4400 | L16: 5600 | M16: 4400 | N16: 4600 | O16: 5900 | P16: 4500 | Q16: 5100 | R16: 5100 | S16: 4500 | T16: 4500 | U16: 5000 | V16: 6800 | W16: 4400 | X16: 5400 | Y16: 4600 | Z16: 118550 | AA16: 24 | AB16: 0.1394
A17: 4000061 | B17: 12350 | C17: 12500 | D17: 11400 | E17: 13300 | F17: 13150 | G17: 11200 | H17: 10250 | I17: 11500 | J17: 12850 | K17: 12900 | L17: 13700 | M17: 12700 | N17: 13700 | O17: 13700 | P17: 12850 | Q17: 12950 | R17: 12150 | S17: 12150 | T17: 10950 | U17: 11900 | V17: 14550 | W17: 13400 | X17: 12550 | Y17: 14350 | Z17: 303000 | AA17: 24 | AB17: 0.0826
A18: 4000065 | B18: 93100 | C18: 91900 | D18: 84400 | E18: 81500 | F18: 79900 | G18: 71000 | H18: 75600 | I18: 77500 | J18: 86700 | K18: 80200 | L18: 86200 | M18: 87100 | N18: 82500 | O18: 82600 | P18: 78020 | Q18: 81900 | R18: 83002 | S18: 72000 | T18: 63100 | U18: 76300 | V18: 88900 | W18: 95100 | X18: 76300 | Y18: 89500 | Z18: 1964322 | AA18: 24 | AB18: 0.0898
A19: 4000066 | B19: 225 | C19: 350 | D19: 375 | E19: 150 | F19: 200 | G19: 325 | H19: 75 | I19: 25 | J19: 200 | K19: 250 | L19: 375 | M19: 125 | N19: 250 | O19: 300 | P19: 75 | Q19: 200 | R19: 150 | S19: 300 | T19: 100 | U19: 125 | V19: 200 | W19: 350 | X19: 350 | Y19: 200 | Z19: 5275 | AA19: 24 | AB19: 0.4632
A20: 4000067 | B20: 0 | C20: 150 | D20: 100 | E20: 25 | F20: 100 | G20: 250 | H20: 100 | I20: 50 | J20: 25 | K20: 75 | L20: 100 | M20: 75 | N20: 125 | O20: 125 | P20: 25 | Q20: 0 | R20: 25 | S20: 200 | T20: 25 | U20: 25 | V20: 50 | W20: 100 | X20: 125 | Y20: 0 | Z20: 1875 | AA20: 21 | AB20: 0.807
A21: 4000072 | B21: 1744 | C21: 1898 | D21: 2000 | E21: 1592 | F21: 1405 | G21: 1413 | H21: 1230 | I21: 1922 | J21: 1646 | K21: 1396 | L21: 1615 | M21: 1394 | N21: 1406 | O21: 1578 | P21: 1640 | Q21: 1570 | R21: 1654 | S21: 1474 | T21: 859 | U21: 1380 | V21: 1957 | W21: 1856 | X21: 1156 | Y21: 1226 | Z21: 37011 | AA21: 24 | AB21: 0.1764
A22: 4000077 | B22: 700 | C22: 860 | D22: 400 | E22: 1025 | F22: 1125 | G22: 625 | H22: 1000 | I22: 695 | J22: 775 | K22: 875 | L22: 725 | M22: 850 | N22: 615 | O22: 1075 | P22: 1100 | Q22: 775 | R22: 951 | S22: 1160 | T22: 575 | U22: 807 | V22: 1325 | W22: 725 | X22: 1150 | Y22: 1060 | Z22: 20973 | AA22: 24 | AB22: 0.2526
... A83: 4000455 | B83: 0 | C83: 10 | D83: 0 | E83: 10 | F83: 0 | G83: 20 | H83: 10 | I83: 0 | J83: 0 | K83: 0 | L83: 10 | M83: 10 | N83: 0 | O83: 0 | P83: 20 | Q83: 0 | R83: 10 | S83: 10 | T83: 0 | U83: 20 | V83: 0 | W83: 10 | X83: 10 | Y83: 0 | Z83: 150 | AA83: 12 | AB83: 1.1136
A84: 4000457 | B84: 0 | C84: 0 | D84: 0 | E84: 0 | F84: 0 | G84: 0 | H84: 0 | I84: 0 | J84: 0 | K84: 0 | L84: 100 | M84: 150 | N84: 110 | O84: 0 | P84: 0 | Q84: 0 | R84: 100 | S84: 0 | T84: 0 | U84: 0 | V84: 0 | W84: 0 | X84: 0 | Y84: 0 | Z84: 460 | AA84: 4 | AB84: 2.2788 | AC84: NY_ARTIKKEL
A85: 4000740 | B85: 123 | C85: 152 | D85: 153 | E85: 102 | F85: 77 | G85: 198 | H85: 89 | I85: 132 | J85: 150 | K85: 144 | L85: 128 | M85: 152 | N85: 128 | O85: 167 | P85: 143 | Q85: 138 | R85: 142 | S85: 169 | T85: 105 | U85: 162 | V85: 186 | W85: 136 | X85: 152 | Y85: 214 | Z85: 3442 | AA85: 24 | AB85: 0.2175
A86: 4000755 | B86: 5400 | C86: 3800 | D86: 4800 | E86: 5000 | F86: 4600 | G86: 4200 | H86: 3000 | I86: 3600 | J86: 4200 | K86: 4800 | L86: 6400 | M86: 3800 | N86: 4800 | O86: 4200 | P86: 5000 | Q86: 3800 | R86: 5000 | S86: 4200 | T86: 2800 | U86: 3200 | V86: 5800 | W86: 3400 | X86: 4800 | Y86: 4600 | Z86: 105200 | AA86: 24 | AB86: 0.1953
A87: 4000758 | B87: 230 | C87: 170 | D87: 240 | E87: 100 | F87: 220 | G87: 160 | H87: 160 | I87: 190 | J87: 310 | K87: 230 | L87: 190 | M87: 190 | N87: 260 | O87: 230 | P87: 270 | Q87: 200 | R87: 300 | S87: 230 | T87: 160 | U87: 120 | V87: 290 | W87: 240 | X87: 200 | Y87: 140 | Z87: 5030 | AA87: 24 | AB87: 0.2571
A88: 4000759 | B88: 110 | C88: 150 | D88: 130 | E88: 140 | F88: 250 | G88: 60 | H88: 120 | I88: 40 | J88: 130 | K88: 130 | L88: 140 | M88: 180 | N88: 60 | O88: 150 | P88: 140 | Q88: 80 | R88: 170 | S88: 220 | T88: 100 | U88: 40 | V88: 120 | W88: 140 | X88: 110 | Y88: 90 | Z88: 3000 | AA88: 24 | AB88: 0.3973
A89: 4000760 | B89: 20 | C89: 10 | D89: 60 | E89: 20 | F89: 110 | G89: 20 | H89: 30 | I89: 40 | J89: 30 | K89: 60 | L89: 70 | M89: 60 | N89: 50 | O89: 30 | P89: 20 | Q89: 40 | R89: 110 | S89: 60 | T89: 10 | U89: 30 | V89: 100 | W89: 120 | X89: 40 | Y89: 100 | Z89: 1240 | AA89: 24 | AB89: 0.6435
A90: 4000761 | B90: 120 | C90: 130 | D90: 60 | E90: 150 | F90: 210 | G90: 70 | H90: 130 | I90: 110 | J90: 120 | K90: 80 | L90: 100 | M90: 50 | N90: 60 | O90: 120 | P90: 60 | Q90: 110 | R90: 122 | S90: 180 | T90: 120 | U90: 110 | V90: 110 | W90: 130 | X90: 160 | Y90: 106 | Z90: 2718 | AA90: 24 | AB90: 0.3334
A91: 4000763 | B91: 55 | C91: 56 | D91: 28 | E91: 54 | F91: 44 | G91: 39 | H91: 46 | I91: 43 | J91: 29 | K91: 42 | L91: 38 | M91: 37 | N91: 54 | O91: 55 | P91: 45 | Q91: 34 | R91: 57 | S91: 47 | T91: 52 | U91: 27 | V91: 38 | W91: 33 | X91: 36 | Y91: 43 | Z91: 1032 | AA91: 24 | AB91: 0.2131
A92: 4000764 | B92: 26 | C92: 23 | D92: 20 | E92: 35 | F92: 30 | G92: 32 | H92: 30 | I92: 41 | J92: 25 | K92: 37 | L92: 34 | M92: 37 | N92: 33 | O92: 30 | P92: 30 | Q92: 40 | R92: 27 | S92: 31 | T92: 23 | U92: 17 | V92: 24 | W92: 22 | X92: 25 | Y92: 19 | Z92: 691 | AA92: 24 | AB92: 0.2244
A93: 4000765 | B93: 18 | C93: 9 | D93: 8 | E93: 1 | F93: 5 | G93: 7 | H93: 7 | I93: 2 | J93: 14 | K93: 2 | L93: 5 | M93: 12 | N93: 2 | O93: 8 | P93: 7 | Q93: 3 | R93: 9 | S93: 6 | T93: 1 | U93: 2 | V93: 7 | W93: 6 | X93: 29 | Y93: 9 | Z93: 179 | AA93: 24 | AB93: 0.8146
A94: 4000766 | B94: 75 | C94: 25 | D94: 175 | E94: 125 | F94: 25 | G94: 75 | H94: 50 | I94: 25 | J94: 25 | K94: 75 | L94: 75 | M94: 125 | N94: 25 | O94: 150 | P94: 75 | Q94: 50 | R94: 0 | S94: 175 | T94: 50 | U94: 50 | V94: 50 | W94: 75 | X94: 50 | Y94: 25 | Z94: 1650 | AA94: 23 | AB94: 0.6904
A95: 4000767 | B95: 250 | C95: 225 | D95: 275 | E95: 275 | F95: 275 | G95: 250 | H95: 275 | I95: 325 | J95: 325 | K95: 325 | L95: 275 | M95: 150 | N95: 350 | O95: 450 | P95: 250 | Q95: 300 | R95: 375 | S95: 250 | T95: 250 | U95: 425 | V95: 225 | W95: 375 | X95: 250 | Y95: 425 | Z95: 7150 | AA95: 24 | AB95: 0.2385
A96: 4000768 | B96: 400 | C96: 250 | D96: 225 | E96: 225 | F96: 100 | G96: 225 | H96: 150 | I96: 275 | J96: 375 | K96: 200 | L96: 350 | M96: 250 | N96: 425 | O96: 300 | P96: 275 | Q96: 250 | R96: 225 | S96: 250 | T96: 200 | U96: 250 | V96: 325 | W96: 275 | X96: 375 | Y96: 225 | Z96: 6400 | AA96: 24 | AB96: 0.2847
... A113: 4000791 | B113: 100 | C113: 200 | D113: 150 | E113: 150 | F113: 300 | G113: 150 | H113: 300 | I113: 100 | J113: 150 | K113: 300 | L113: 300 | M113: 100 | N113: 150 | O113: 150 | P113: 200 | Q113: 100 | R113: 150 | S113: 50 | T113: 50 | U113: 250 | V113: 150 | W113: 350 | X113: 150 | Y113: 150 | Z113: 4200 | AA113: 24 | AB113: 0.4666
A114: 4000793 | B114: 0 | C114: 30 | D114: 0 | E114: 0 | F114: 0 | G114: 0 | H114: 0 | I114: 0 | J114: 0 | K114: 0 | L114: 0 | M114: 0 | N114: 0 | O114: 0 | P114: 0 | Q114: 0 | R114: 0 | S114: 0 | T114: 0 | U114: 0 | V114: 0 | W114: 0 | X114: 0 | Y114: 0 | Z114: 30 | AA114: 1 | AB114: 4.7958 | AC114: NY_ARTIKKEL
A115: 4000795 | B115: 40 | C115: 40 | D115: 0 | E115: 0 | F115: 10 | G115: 0 | H115: 0 | I115: 0 | J115: 0 | K115: 0 | L115: 30 | M115: 25 | N115: 30 | O115: 20 | P115: 30 | Q115: 40 | R115: 0 | S115: 0 | T115: 0 | U115: 5 | V115: 10 | W115: 10 | X115: 10 | Y115: 10 | Z115: 310 | AA115: 14 | AB115: 1.1226
A116: 4000800 | B116: 2400 | C116: 4300 | D116: 4400 | E116: 1200 | F116: 2800 | G116: 1900 | H116: 3000 | I116: 3100 | J116: 3100 | K116: 4400 | L116: 3100 | M116: 3700 | N116: 2100 | O116: 4700 | P116: 4500 | Q116: 3500 | R116: 5200 | S116: 3400 | T116: 2800 | U116: 3800 | V116: 3400 | W116: 2800 | X116: 2700 | Y116: 3000 | Z116: 79300 | AA116: 24 | AB116: 0.2826
A117: 4000801 | B117: 3500 | C117: 5100 | D117: 5050 | E117: 3200 | F117: 4600 | G117: 4200 | H117: 4200 | I117: 4200 | J117: 2300 | K117: 4910 | L117: 4110 | M117: 6000 | N117: 4080 | O117: 4930 | P117: 6970 | Q117: 3500 | R117: 6700 | S117: 5210 | T117: 3315 | U117: 4400 | V117: 3875 | W117: 4100 | X117: 4000 | Y117: 6500 | Z117: 108950 | AA117: 24 | AB117: 0.2464
A118: 4000802 | B118: 1590 | C118: 2278 | D118: 1490 | E118: 2114 | F118: 1688 | G118: 2334 | H118: 1768 | I118: 2254 | J118: 1862 | K118: 2220 | L118: 1831 | M118: 2480 | N118: 1534 | O118: 3162 | P118: 2678 | Q118: 2852 | R118: 2480 | S118: 3272 | T118: 1575 | U118: 1564 | V118: 2986 | W118: 2644 | X118: 2794 | Y118: 2834 | Z118: 54284 | AA118: 24 | AB118: 0.2424
...

Sheet EKKO
A1: 🟢 EKKO
A3: Totalt antall innkjøpsordre | B3: =COUNTA(A11:A13164) -> 13154
A4: Unike EBELN | B4: =COUNTA(A11:A13164) -> 13154
A5: Første ordrenummer | B5: =MIN(A11:A13164) -> 4500145151
A6: Siste ordrenummer | B6: =MAX(A11:A13164) -> 4500245516
A7: Antall ordre (intervall) | B7: =B6-B5+1 -> 100366
A8: Datakvalitet | B8: OK
A10: EBELN
A11: 4500145151
A12: 4500145156
A13: 4500145159
A14: 4500145163
A15: 4500145167
A16: 4500145171
A17: 4500145175
A18: 4500145178
A19: 4500145182
A20: 4500145187
A21: 4500145191
A22: 4500145197
... A13164: 4500245516

Sheet EKPO
A1: 🟢 EKPO
A3: Antall unike MATNR | B3: 529
A4: Total NETWR (NOK) | B4: 63239833
A5: Snitt ORDER_COUNT | B5: 15.22
A6: Høyeste NETWR (artikkel) | B6: 2192400
A7: Totalt filtrerte rader | B7: 8189
A8: Filter | B8: WERKS=3300, LGORT=3001
A10: MATNR | B10: TOTAL_NETWR | C10: ORDER_COUNT | D10: AVG_ORDER_QTY
A11: 4036674 | B11: 2192400 | C11: 20 | D11: 10.5
A12: 4033674 | B12: 1909440 | C12: 42 | D12: 10.62
A13: 4002742 | B13: 1827730 | C13: 16 | D13: 25.63
A14: 4036677 | B14: 1805760 | C14: 21 | D14: 6.86
A15: 4006235 | B15: 1632960 | C15: 7 | D15: 18
A16: 4004825 | B16: 1374600 | C16: 55 | D16: 16.8
A17: 4033646 | B17: 1360800 | C17: 11 | D17: 10.91
A18: 4005583 | B18: 1329919.2 | C18: 11 | D18: 697.73
A19: 4000005 | B19: 1191779.5 | C19: 10 | D19: 65
A20: 4006561 | B20: 938832 | C20: 14 | D20: 24
A21: 4009081 | B21: 916510 | C21: 30 | D21: 7.3
A22: 4006560 | B22: 887714 | C22: 51 | D22: 2
... A539: 4008209 | B539: 0.02 | C539: 1 | D539: 2

Sheet EKBE
A1: 🟢 EKBE
A3: Filter | B3: BEWTP=E, BWART=101
A4: Totalt filtrerte rader | B4: 9004
A5: Antall S-rader (mottak) | B5: 9004
A6: Antall H-rader (retur) | B6: 0
A7: Returandel H% | B7: 0
A8: Total NET_RECEIVED | B8: 134215.69
A10: MATNR | B10: NET_RECEIVED
A11: 4000005 | B11: 650
A12: 4000009 | B12: 60
A13: 4000023 | B13: 816
A14: 4000024 | B14: 432
A15: 4000027 | B15: 60
A16: 4000066 | B16: 184
A17: 4000067 | B17: 64
A18: 4000084 | B18: 42
A19: 4000090 | B19: 282
A20: 4000108 | B20: 791
A21: 4000273 | B21: 6544
A22: 4000286 | B22: 100
... A539: 4048468 | B539: 24

Sheet EINA_EINE
A1: 🟢 EINA_EINE
A3: Antall MATNR med leveringstid | B3: 52
A4: Snitt LEAD_TIME_DAYS | B4: 3.5
A5: Min LEAD_TIME_DAYS | B5: 0
A6: Maks LEAD_TIME_DAYS | B6: 5
A7: Antall med > 1 leverandør | B7: =COUNTIF(C11:C62,">1") -> 6
A8: Andel med leveringstid > 3 dager | B8: =COUNTIF(B11:B62,">3")/COUNTA(B11:B62) -> 0.32692308
A10: MATNR | B10: LEAD_TIME_DAYS | C10: SUPPLIER_COUNT
A11: 4000090 | B11: 5 | C11: 1
A12: 4000286 | B12: 3 | C12: 1
A13: 4000287 | B13: 3 | C13: 1
A14: 4000288 | B14: 3 | C14: 1
A15: 4000835 | B15: 3 | C15: 1
A16: 4000989 | B16: 5 | C16: 1
A17: 4001331 | B17: 5 | C17: 1
A18: 4001523 | B18: 3 | C18: 1
A19: 4001524 | B19: 0 | C19: 1
A20: 4002495 | B20: 3 | C20: 1
A21: 4002667 | B21: 3 | C21: 1
A22: 4002679 | B22: 3 | C22: 1
... A62: 4049107 | B62: 1.5 | C62: 2

Sheet T023T
A1: 🟢 T023T
A3: Antall unike varegrupper (MATKL) | B3: 90
A4: Totalt antall rader | B4: =COUNTA(A11:A100) -> 90
A5: Lengste varegruppenavn (tegn) | B5: {=MAX(LEN(B11:B100))} -> 20
A6: Korteste varegruppenavn (tegn) | B6: {=MIN(LEN(B11:B100))} -> 6
A7: Snitt navnlengde (tegn) | B7: {=AVERAGE(LEN(B11:B100))} -> 17.288889
A8: Datakvalitet | B8: OK | H8: og
A10: MATKL | B10: WGBEZ
A11: 10020403 | B11: Blodsubst/infusjonop
A12: 10030101 | B12: Endosk prod forbr
A13: 10030102 | B13: Gastrostomi forbr
A14: 10030201 | B14: Kar/thor kir forbr
A15: 10030303 | B15: Invasiv kardiologi
A16: 10030398 | B16: Inv kardio forbr.mat
A17: 10030403 | B17: Nevrokirurgiske impl
A18: 10030404 | B18: Tann/Orale implantat
A19: 10030405 | B19: Nevrokirurgisk forbr
A20: 10030501 | B20: Artroskopi
A21: 10030503 | B21: Gips og ortoser
A22: 10030506 | B22: Ortopedi forbr
... A100: 20040903 | B100: Verneutstyr

Sheet MASTERFILE
A1: 🔴 MASTERFILE
A3: Antall artikler i MASTERFILE | B3: =COUNTA(A11:A719) -> 709
A4: Antall kildetabeller koblet | B4: 10
A5: Dekningsprosent ZZXYZ | B5: =COUNTIF(H11:H719,"<>")/COUNTA(A11:A719) -> 0.55571227
A6: Dekningsprosent UNIT_PRICE | B6: =COUNTIF(J11:J719,"<>")/COUNTA(A11:A719) -> 0.99858956
A7: Dekningsprosent CV | B7: =COUNTIF(N11:N719,"<>")/COUNTA(A11:A719) -> 0.96897038
A8: Dekningsprosent LEAD_TIME_DAYS | B8: =COUNTIF(T11:T719,"<>")/COUNTA(A11:A719) -> 0.059238364
A10: MATNR | B10: MAKTX | C10: MTART | D10: MATKL | E10: WGBEZ | F10: MEINS | G10: ZZABC | H10: ZZXYZ | I10: MARC_ABC | J10: UNIT_PRICE | K10: TOTAL_STOCK | L10: D_ANNUAL | M10: ACTIVE_MONTHS | N10: CV | O10: MSEG_STATUS | P10: TOTAL_NETWR | Q10: ORDER_COUNT | R10: AVG_ORDER_QTY | S10: NET_RECEIVED | T10: LEAD_TIME_DAYS | U10: SUPPLIER_COUNT
A11: 4000005 | B11: Filter steril Diasafe Plus | C11: ZHAW | D11: 10080301 | E11: Forbr BHM Dialyseuts | F11: STK | H11: X | I11: C | J11: 2064.73 | K11: 52 | L11: 654 | M11: 16 | N11: 0.9697 | P11: 1191779.5 | Q11: 10 | R11: 65 | S11: 650
A12: 4000014 | B12: Forstøverbeger medikament m/munnstykke | C12: ZHAW | D12: 10050505 | E12: Oksygenbehandling | F12: STK | G12: A | H12: X | I12: C | J12: 10.25 | K12: 302 | L12: 29627 | M12: 24 | N12: 0.1583
A13: 4000023 | B13: Ernæringssett Infinity pack | C13: ZHAW | D13: 10080401 | E13: Forbr BHM Ernærsyst | F13: STK | G13: A | H13: Y | J13: 23.41 | K13: 574 | L13: 24305 | M13: 24 | N13: 0.1716 | P13: 515990.4 | Q13: 17 | R13: 48 | S13: 816
A14: 4000024 | B14: Ernæringssett Flocare Infin mobil | C14: ZHAW | D14: 10080401 | E14: Forbr BHM Ernærsyst | F14: STK | G14: A | H14: Y | J14: 22.39 | K14: 2130 | L14: 12900 | M14: 24 | N14: 1.1109 | P14: 270685.44 | Q14: 9 | R14: 48 | S14: 432
A15: 4000027 | B15: Sonde ernæring ENFit Ch6/60cm | C15: ZHAW | D15: 10080401 | E15: Forbr BHM Ernærsyst | F15: STK | G15: C | H15: Y | I15: C | J15: 39.69 | K15: 184 | L15: 595 | M15: 23 | N15: 0.681 | P15: 24686.24 | Q15: 15 | R15: 4 | S15: 60
A16: 4000060 | B16: Kran 3-veis luerlock u/slange | C16: ZHAW | D16: 10050103 | E16: Infusjon/transfj. Pr | F16: STK | G16: B | H16: X | I16: C | J16: 2.77 | K16: 1900 | L16: 118550 | M16: 24 | N16: 0.1394
A17: 4000061 | B17: Kran 3-veis m/slange 10cm | C17: ZHAW | D17: 10050103 | E17: Infusjon/transfj. Pr | F17: STK | G17: A | H17: X | I17: B | J17: 4.26 | K17: 2600 | L17: 303000 | M17: 24 | N17: 0.0826
A18: 4000065 | B18: Propp kombi luer/luerlock rød | C18: ZHAW | D18: 10050103 | E18: Infusjon/transfj. Pr | F18: STK | G18: A | H18: X | I18: A | J18: 0.2602 | K18: 7000 | L18: 1964322 | M18: 24 | N18: 0.0898
A19: 4000066 | B19: Kanyle spinal svart 22Gx88mm | C19: ZHAW | D19: 10050102 | E19: Anestesi kanyler | F19: STK | G19: C | H19: X | I19: C | J19: 6.9 | K19: 150 | L19: 5275 | M19: 24 | N19: 0.4632 | P19: 30820 | Q19: 23 | R19: 8 | S19: 184
A20: 4000069 | B20: Kanyle opptrekk m/lokk/partik filter 5µm | C20: ZHAW | D20: 10050109 | E20: Sprøyter og kanyler | F20: STK | G20: C | H20: X | I20: B | J20: 3.6 | K20: 100
A21: 4000072 | B21: Sprøyte m/kateterspiss 50/60ml | C21: ZHAW | D21: 10050109 | E21: Sprøyter og kanyler | F21: STK | G21: B | H21: X | I21: C | J21: 2.96 | K21: 920 | L21: 37011 | M21: 24 | N21: 0.1764
A22: 4000077 | B22: Knivblad m/skaft suturfjern safety nr12 | C22: ZHAW | D22: 10050606 | E22: Operasjonsprodukter | F22: STK | G22: B | H22: Y | I22: C | J22: 15.7 | K22: 405 | L22: 20973 | M22: 24 | N22: 0.2526
A23: 4000078 | B23: Knivblad opr nr10 | C23: ZHAW | D23: 10050606 | E23: Operasjonsprodukter | F23: STK | G23: C | H23: X | I23: C | J23: 1.4158 | K23: 1300 | L23: 11900 | M23: 22 | N23: 1.0275
A24: 4000084 | B24: Autoklavetape dampster blå 18mmx55m | C24: ZHAW | D24: 10030805 | E24: Steriliseringstester | F24: RUL | G24: C | H24: X | I24: C | J24: 38.18 | K24: 129 | L24: 1168 | M24: 24 | N24: 0.3791 | P24: 45826.56 | Q24: 22 | R24: 2 | S24: 42
A25: 4000090 | B25: Filmbandasje 6x7cm | C25: ZHAW | D25: 10050801 | E25: Sårbehandlingsproduk | F25: STK | G25: B | I25: C | J25: 6.73 | K25: 2700 | L25: 34586 | M25: 21 | N25: 0.5762 | P25: 191655.84 | Q25: 27 | R25: 10.07 | S25: 282 | T25: 5 | U25: 1
A26: 4000094 | B26: Film fiksering IV kanyle 7x8cm | C26: ZHAW | D26: 10050502 | E26: Fikseringsprodukter | F26: STK | G26: A | H26: Y | I26: C | J26: 3.57 | K26: 3100 | L26: 452000 | M26: 24 | N26: 0.0989
A27: 4000108 | B27: Engangsblad standard til kir klipper | C27: ZHAW | D27: 10050606 | E27: Operasjonsprodukter | F27: STK | G27: A | H27: Y | I27: C | J27: 16.94 | K27: 2899 | L27: 38001 | M27: 24 | N27: 0.2275 | P27: 631652 | Q27: 67 | R27: 12.16 | S27: 791
A28: 4000273 | B28: Sprøyte prefylt NaCl 0,9% SP 5ml | C28: ZHAW | D28: 10050109 | E28: Sprøyter og kanyler | F28: STK | G28: A | H28: Y | I28: B | J28: 2.05 | K28: 6120 | L28: 478770 | M28: 24 | N28: 0.0815 | P28: 416540.96 | Q28: 18 | R28: 363.56 | S28: 6544
A29: 4000274 | B29: Sprøyte prefylt NaCl 0,9% SP 10ml | C29: ZHAW | D29: 10050109 | E29: Sprøyter og kanyler | F29: STK | G29: A | H29: X | I29: A | J29: 2.11 | K29: 10860 | L29: 1683680 | M29: 24 | N29: 0.0804
A30: 4000275 | B30: Kanyle injeksjon safety blå 23Gx25mm | C30: ZHAW | D30: 10050109 | E30: Sprøyter og kanyler | F30: STK | G30: C | H30: X | I30: C | J30: 0.755 | K30: 2600 | L30: 86550 | M30: 24 | N30: 0.1254
A31: 4000276 | B31: Kanyle injeksjon safety grønn 21Gx40mm | C31: ZHAW | D31: 10050109 | E31: Sprøyter og kanyler | F31: STK | G31: C | H31: X | I31: C | J31: 0.76 | K31: 900 | L31: 115300 | M31: 24 | N31: 0.1448
A32: 4000279 | B32: Holder til blodprøvetakingskanyle 5-10ml | C32: ZHAW | D32: 10040101 | E32: Blodprøvetakingsutst | F32: STK | G32: B | H32: Y | I32: C | J32: 0.3138 | K32: 1212 | L32: 116095 | M32: 24 | N32: 0.1365
A33: 4000286 | B33: PVK safety m/brønn blå 22Gx25mm | C33: ZHAW | D33: 10050108 | E33: Venekanyl/-port/-nål | F33: STK | G33: A | H33: X | I33: B | J33: 6.77 | K33: 1200 | L33: 193850 | M33: 24 | N33: 0.1183 | P33: 34500 | Q33: 1 | R33: 100 | S33: 100 | T33: 3 | U33: 1
A34: 4000287 | B34: PVK safety m/brønn rosa 20Gx32mm | C34: ZHAW | D34: 10050108 | E34: Venekanyl/-port/-nål | F34: STK | G34: A | H34: X | I34: B | J34: 6.71 | K34: 2950 | L34: 163050 | M34: 24 | N34: 0.1144 | T34: 3 | U34: 1
A35: 4000288 | B35: PVK safety m/brønn grønn 18Gx32mm | C35: ZHAW | D35: 10050108 | E35: Venekanyl/-port/-nål | F35: STK | G35: A | H35: X | I35: B | J35: 6.75 | K35: 1000 | L35: 151700 | M35: 24 | N35: 0.1196 | P35: 37950 | Q35: 1 | R35: 110 | S35: 110 | T35: 3 | U35: 1
A36: 4000290 | B36: PVK safety m/brønn grå 16Gx45mm | C36: ZHAW | D36: 10050108 | E36: Venekanyl/-port/-nål | F36: STK | G36: C | H36: X | I36: C | J36: 6.77 | K36: 700 | L36: 10500 | M36: 24 | N36: 0.29 | P36: 56060 | Q36: 9 | R36: 20 | S36: 180
A37: 4000291 | B37: PVK safety m/brønn oransje 14Gx45mm | C37: ZHAW | D37: 10050108 | E37: Venekanyl/-port/-nål | F37: STK | G37: C | H37: X | I37: C | J37: 7.09 | K37: 350 | L37: 1750 | M37: 19 | N37: 0.7401 | P37: 19376 | Q37: 11 | R37: 4 | S37: 40
A38: 4000310 | B38: Sugesett kon tupp m/fingrkontr 3,5m | C38: ZHAW | D38: 10050609 | E38: Sug, slanger og pose | F38: STK | G38: B | H38: X | I38: C | J38: 33.54 | K38: 124 | L38: 5519 | M38: 24 | N38: 0.1831
A39: 4000311 | B39: Sugeslange kon elastisk tupp 3,5m | C39: ZHAW | D39: 10050609 | E39: Sug, slanger og pose | F39: STK | G39: C | H39: X | I39: C | J39: 32.99 | K39: 164 | L39: 3444 | M39: 24 | N39: 0.6935
A40: 4000312 | B40: Sugesett opr dobbelrør abdominal 3,5m | C40: ZHAW | D40: 10050609 | E40: Sug, slanger og pose | F40: STK | G40: C | H40: X | I40: C | J40: 38.44 | K40: 136 | L40: 2206 | M40: 24 | N40: 0.1884
A41: 4000313 | B41: Sugeslange elastisk del 1m microkir 3,5m | C41: ZHAW | D41: 10050609 | E41: Sug, slanger og pose | F41: STK | G41: B | H41: X | I41: C | J41: 76.45 | K41: 80 | L41: 2500 | M41: 24 | N41: 0.2415
A42: 4000314 | B42: Utbyttepose sårdren opr 700ml | C42: ZHAW | D42: 10050610 | E42: Sårdren | F42: STK | G42: B | I42: C | J42: 20.04 | K42: 1040 | L42: 15959 | M42: 24 | N42: 0.2292 | P42: 261550 | Q42: 26 | R42: 11.92 | S42: 334
...

Sheet KVALITETSRAPPORT
A1: 🔴 KVALITETSRAPPORT
A3: Generert dato | B3: =TODAY() -> 46094
A4: Antall artikler i MASTERFILE | B4: =COUNTA(MASTERFILE!A11:A719) -> 709
A5: Antall med NY_ARTIKKEL status | B5: =COUNTIF(MASTERFILE!O11:O719,"NY_ARTIKKEL") -> 44
A6: Felt med lavest dekning | B6: LEAD_TIME_DAYS
A7: Felt med høyest dekning | B7: UNIT_PRICE
A8: Dekningsterskel (OK) | B8: 0.8
A10: Felt | B10: Antall | C10: Av total | D10: Dekning (%) | E10: Status
A11: ZZXYZ | B11: =COUNTIF(MASTERFILE!H11:H719,"<>") -> 394 | C11: =COUNTA(MASTERFILE!A11:A719) -> 709 | D11: =B11/C11 -> 0.55571227 | E11: =IF(D11>=0.8,"✅ OK","⚠️ LAV") -> ⚠️ LAV
A12: UNIT_PRICE | B12: =COUNTIF(MASTERFILE!J11:J719,"<>") -> 708 | C12: =COUNTA(MASTERFILE!A11:A719) -> 709 | D12: =B12/C12 -> 0.99858956 | E12: =IF(D12>=0.8,"✅ OK","⚠️ LAV") -> ✅ OK
A13: CV | B13: =COUNTIF(MASTERFILE!N11:N719,"<>") -> 687 | C13: =COUNTA(MASTERFILE!A11:A719) -> 709 | D13: =B13/C13 -> 0.96897038 | E13: =IF(D13>=0.8,"✅ OK","⚠️ LAV") -> ✅ OK
A14: TOTAL_NETWR | B14: =COUNTIF(MASTERFILE!P11:P719,"<>") -> 505 | C14: =COUNTA(MASTERFILE!A11:A719) -> 709 | D14: =B14/C14 -> 0.7122708 | E14: =IF(D14>=0.8,"✅ OK","⚠️ LAV") -> ⚠️ LAV
A15: LEAD_TIME_DAYS | B15: =COUNTIF(MASTERFILE!T11:T719,"<>") -> 42 | C15: =COUNTA(MASTERFILE!A11:A719) -> 709 | D15: =B15/C15 -> 0.059238364 | E15: =IF(D15>=0.8,"✅ OK","⚠️ LAV") -> ⚠️ LAV
A17: SPESIALSTATISTIKK
A18: Antall MSEG_STATUS = NY_ARTIKKEL | B18: =COUNTIF(MASTERFILE!O11:O719,"NY_ARTIKKEL") -> 44
